Workbook

Sheet Read Me
B1: PRODIGEE FINANCE LIMITED — BM AUDIO/VIDEO FI · SUCCESS CRITERIA SCORECARD V1.0
B2: Aligned to LAP Credit Policy V2.3 · Companion to BM_FI_Success_Criteria_Framework_V1.docx · The FI is a 10–15 minute genuineness & right-file check — NOT a PD.
B4: HOW TO USE
B5: 1. Open the 'Scorecard' sheet. Fill ONLY the yellow cells: header details, Coverage (Full / Partial / None / N/A) and gate Results (PASS/FAIL).
B6: 2. Coverage: Full = completely covered and checked against the application form / BPS output in hand · Partial = touched but not probed/confirmed · None = not covered · N/A = not applicable (points leave the denominator).
B7: 3. Score, subtotals, band and verdict calculate automatically. Minimum pass: Score ≥ 75 AND all 7 gates PASS AND no open red flag.
B8: 4. The 'Gap & Coaching Report' sheet fills itself — every missed/incomplete item with the exact question to ask next time. Clear list = 100. Target 90+.
B9: 5. The BM's FORWARD/REJECT decision is separate from the score — a well-reasoned REJECT on a weak file is a successful FI.
B10: 6. NEW — 'Call Summary' sheet: a one-page management digest of the FI call under three heads — Genuineness & Customer Awareness, Sourcing & Channel Integrity, and Prima Facie Eligibility (income vs policy gates, bureau, collateral) — plus red flags and the BM decision, so management reads the summary instead of hearing the recording. Header, totals, policy-gate checks and verdict fill automatically from the Scorecard.

Sheet Scorecard
A1: BM AUDIO/VIDEO FI — SUCCESS CRITERIA SCORECARD (V1.0) · Business Loan Against Property
A2: Application ID | B2: Not provided (application form not shared with evaluator) | C2: Evaluator (AI Agent / Reviewer) | D2: Claude (AI Evaluation Agent) for Atanu Pandey — 19-Aug-2026
A3: Customer Name | B3: Not clearly captured on audio (male borrower; dairy/milk-aggregation business, village near Biaora/Bhyavra)
A4: BM Name | B4: Lalit Gujar (self-introduced ~0:05, Prodigee Finance branch, Bhyavra/Biaora)
A5: Date of FI Call | B5: 17-Aug-2026 (from recording file metadata)
A6: Recording Duration (min) | B6: 8.5
A7: Loan Amount (Rs.) | B7: 800,000 (as stated by customer ~4:45; application amount not provided)
A9: ID | B9: Success Criterion | C9: What the BM must ask / verify (sample probe) | D9: Reference | E9: Critical | F9: Max Pts | G9: Coverage | H9: Pts Scored | I9: Remarks / evidence (timestamp)
A10: SECTION A — CALL OPENING, IDENTITY & CONSENT (window 0:00–1:30) | I10: 12
A11: A1 | B11: Recording/video disclosure made at the start of the call | C11: “Yeh call/video recording par hai, aapke loan verification ke liye.” — within the first 60 seconds. | D11: RBI Fair Practices; Gate K3 | E11: YES | F11: 3 | G11: None | H11: =IF(G11="N/A",0,F11*IF(G11="Full",1,IF(G11="Partial",0.5,0))) -> 0 | I11: No recording/consent disclosure heard anywhere in 0:00–1:00 opening (checked on two independent ASR passes). Opening is greeting + self-intro only (0:00–0:25).
A12: A2 | B12: Speaking to the MAIN BORROWER — video face verification | C12: “Aap khud [poora naam] bol rahe hain? Yeh number aapka hi hai?” On video: face clearly visible and matching the KYC photo. | D12: Application form; Gate K2 | E12: YES | F12: 3 | G12: Partial | H12: =IF(G12="N/A",0,F12*IF(G12="Full",1,IF(G12="Partial",0.5,0))) -> 1.5 | I12: AUDIO-only call — no video/face-match possible. BM speaks directly to the borrower who answers own-file details (dairy, loans, property), but explicit name/self confirmation not heard (0:00–0:56).
A13: A3 | B13: Application awareness confirmed | C13: “Aapne Prodigee Finance mein loan ke liye file lagayi hai?” — unaware = FI-RF-1 (possible fraud). | D13: FI-RF-1 | E13: YES | F13: 3 | G13: Full | H13: =IF(G13="N/A",0,F13*IF(G13="Full",1,IF(G13="Partial",0.5,0))) -> 3 | I13: 0:05–0:25 — 'Aapne file lagayi thi... Prodigee Finance mein?' — customer confirms application and knows the company; also names whom he gave the file to (0:26–0:52).
A14: A4 | B14: Language comfort, audio & video quality | C14: Customer's language; confirm they can hear/see and understand; no repeated breakdowns. | D14: Call quality | E14: — | F14: 3 | G14: Full | H14: =IF(G14="N/A",0,F14*IF(G14="Full",1,IF(G14="Partial",0.5,0))) -> 3 | I14: Call held in customer's own dialect-Hindi; conversation flows end-to-end without language/volume breakdowns. (Recording itself is audible; quality issues scored under G1.)
A15: SECTION B — SOURCING & CHANNEL INTEGRITY (window 1:30–3:00) | I15: 16
A16: B1 | B16: RM visit verified — who sourced and visited | C16: “Aap tak yeh loan kaise pahuncha? Prodigee se kaun aaya tha — naam? Kya woh aapke kaam ki jagah / ghar aaye the?” RM never visited = FI-RF-8. | D16: PRAGATI sourcing record; FI-RF-8 | E16: YES | F16: 4 | G16: Partial | H16: =IF(G16="N/A",0,F16*IF(G16="Full",1,IF(G16="Partial",0.5,0))) -> 2 | I16: 0:26–1:00 — file given to 'Arjun' (Prodigee staff/RM), known to customer ~2 years. BM did NOT ask whether the RM actually visited the home/work premises.
A17: B2 | B17: Agent / broker / DSA involvement probed | C17: “Beech mein koi agent, broker, DSA, connector ya sales agent hai? Kisi ne file lagwane mein madad ki — kaun?” — undisclosed middleman = FI-RF-3 / Gate K6. | D17: Gate K6; FI-RF-3 | E17: YES | F17: 4 | G17: None | H17: =IF(G17="N/A",0,F17*IF(G17="Full",1,IF(G17="Partial",0.5,0))) -> 0 | I17: No agent/broker/DSA/connector question asked at any point on the recording.
A18: B3 | B18: Zero-commission integrity check | C18: “Kya kisi ne is loan ke liye aapse commission, fees ya paisa manga hai? Prodigee mein ZERO COMMISSION policy hai.” PLUS login fee: “Login fee kisne collect ki — Prodigee ke RM ne hi? Kitni di? Receipt mili?” — fee collected by anyone other than the RM = FI-RF-4. Demand = FI-RF-4 (STOP — CCRO). | D18: Zero Commission Policy; FI-RF-4 | E18: YES | F18: 4 | G18: None | H18: =IF(G18="N/A",0,F18*IF(G18="Full",1,IF(G18="Partial",0.5,0))) -> 0 | I18: No zero-commission question and no login-fee (who collected/how much/receipt) check anywhere on the call.
A19: B4 | B19: Sourcing story consistent with PRAGATI | C19: Customer's account (walk-in / reference / RM outreach) matches the sourcing channel recorded on PRAGATI. | D19: PRAGATI record | E19: — | F19: 4 | G19: Partial | H19: =IF(G19="N/A",0,F19*IF(G19="Full",1,IF(G19="Partial",0.5,0))) -> 2 | I19: Sourcing story elicited (via Arjun, 2-year acquaintance ~0:26–1:00) but PRAGATI record not available to evaluator — consistency unverified.
A20: SECTION C — PRODUCT & LOAN UNDERSTANDING (window 3:00–4:30) | I20: 12
A21: C1 | B21: Knows it is a BUSINESS Loan Against Property — mortgage | C21: “Aapko pata hai yeh BUSINESS loan hai jis mein aapki property girvi (mortgage) rakhi jayegi?” — explicit yes. | D21: Policy F.1; Gate K4 | E21: YES | F21: 4 | G21: Partial | H21: =IF(G21="N/A",0,F21*IF(G21="Full",1,IF(G21="Partial",0.5,0))) -> 2 | I21: Property-backed loan is discussed (registry/sale-deed probing 6:32–7:15) but the explicit 'BUSINESS loan, property girvi/mortgage hogi' confirmation was never put to the customer.
A22: C2 | B22: Loan amount stated by the customer | C22: “Kitne amount ki file lagayi hai?” — customer states; BM must NOT lead. ±10% of application; larger gap = FI-RF-2. THEN explain the cost through EMI, not ROI%: “Agar [amount] ka loan [tenure] ke liye hota hai to andaazan EMI ₹[figure] banegi” — rural customers understand EMI for an amount and tenure better than an interest rate; state it as indicative. | D22: Application form; Gate K5 | E22: YES | F22: 4 | G22: Partial | H22: =IF(G22="N/A",0,F22*IF(G22="Full",1,IF(G22="Partial",0.5,0))) -> 2 | I22: ~4:44 BM asks requirement; customer states '8 (lakh) ke aas-paas' unprompted — good. But indicative EMI for amount/tenure never explained. Application amount unavailable for the ±10% check.
A23: C3 | B23: End use understood in brief | C23: “Loan ka paisa kis kaam mein lagega?” — business-linked and not restricted. | D23: Policy B.3 | E23: — | F23: 4 | G23: Partial | H23: =IF(G23="N/A",0,F23*IF(G23="Full",1,IF(G23="Partial",0.5,0))) -> 2 | I23: ~4:50 'Aath lakh ka kya karoge?' — customer: expand/open dairy work (business-linked). CAUTION: if funds buy milch animals this falls on the restricted end-use list — not probed.
A24: SECTION D — INCOME SUFFICIENCY vs CREDIT POLICY (window 4:30–7:30) | I24: 24
A25: D1 | B25: Main business/occupation and vintage — in brief | C25: “Aap kya kaam karte hain? Kaise chalta hai? Kitne saal se?” — vintage ≥ 1 year; occupation not on the negative list. | D25: Policy B.9 / Part J.1 / Part M | E25: — | F25: 6 | G25: Full | H25: =IF(G25="N/A",0,F25*IF(G25="Full",1,IF(G25="Partial",0.5,0))) -> 6 | I25: 1:00–4:40 — occupation probed concretely: milk aggregation ~105 L/day bought in village + ~15 L own (5 buffaloes), sold to Krishna Milk Dairy at ~Rs.51/L, margin Rs.3/L + bonus, cash settlement; brother also in dairy; time-in-business asked (~4:55).
A26: D2 | B26: Income tested against policy gates | C26: “Ghar ki kul mahine ki aamdani kitni? Aap khud kitna kama lete hain?” — household ≥ ₹30,000 (without agri); one earner ≥ ₹15,000. Below gates = FI-RF-5 → reject at BM stage. | D26: Policy C.1/C.2; FI-RF-5 | E26: YES | F26: 6 | G26: Partial | H26: =IF(G26="N/A",0,F26*IF(G26="Full",1,IF(G26="Partial",0.5,0))) -> 3 | I26: BM works the arithmetic with the customer (3:13–4:40: 105 L x Rs.3 + own-milk sale) but never elicits a monthly HOUSEHOLD figure nor tests the Rs.30,000/Rs.15,000 policy gates. Derived gross ~Rs.30–33k/month — BORDERLINE; re-verify.
A27: D3 | B27: Other income streams identified in brief (incl. agriculture) | C27: “Aur koi aamdani — kheti, kiraya, dairy, naukri? Kheti hai to kiske naam, kitne acre?” — identify every stream; any income source the RM did NOT capture on PRAGATI must be noted for the file; depth is for BCM/RCM. | D27: Policy C.4–C.8 | E27: — | F27: 6 | G27: Full | H27: =IF(G27="N/A",0,F27*IF(G27="Full",1,IF(G27="Partial",0.5,0))) -> 6 | I27: 2:03–2:26 — land asked: how much, whose name (father's); buffaloes counted (5); brother's dairy work noted (2:20–2:48). Streams identified with owners.
A28: D4 | B28: BM's sufficiency view formed | C28: Is the income from ALL sources prima facie sufficient to make the customer eligible for the Prodigee LAP loan sought, per Credit Policy? BM states a view on record. | D28: Credit Policy C.2 | E28: — | F28: 6 | G28: Partial | H28: =IF(G28="N/A",0,F28*IF(G28="Full",1,IF(G28="Partial",0.5,0))) -> 3 | I28: BM audibly computes daily saving with the customer (3:35–4:40) — an implicit sufficiency exercise — but states no on-record view that income supports the Rs.8-lakh LAP.
A29: SECTION E — CREDIT BEHAVIOUR vs BPS / BUREAU (window 7:30–9:00) | I29: 16
A30: E1 | B30: Running loans acknowledged vs BPS/bureau | C30: With the BPS output in front: “Abhi kaun-kaun se loan chal rahe hain, kitni EMI?” — reconcile with running-loan types in BPS. | D30: BPS output; FI-RF-6 | E30: YES | F30: 6 | G30: Partial | H30: =IF(G30="N/A",0,F30*IF(G30="Full",1,IF(G30="Partial",0.5,0))) -> 3 | I30: 5:32–6:40 — existing loan ~Rs.3 lakh acknowledged (on the house sold last year; ~Rs.2–2.5 lakh to be cleared from sale proceeds); 'bas aur nahin hai koi loan' (6:41). EMI figure not elicited; BPS output not provided to evaluator for reconciliation.
A31: E2 | B31: Overdues / bounces confronted | C31: Every overdue/bounce on the BPS put to the customer; explanation recorded. Unexplained/denied = FI-RF-6. | D31: BPS output; Policy D.1 | E31: YES | F31: 6 | G31: N/A | H31: =IF(G31="N/A",0,F31*IF(G31="Full",1,IF(G31="Partial",0.5,0))) -> 0 | I31: BPS output not provided to the evaluator and no overdue/bounce was put to the customer on the call — cannot assess. If BPS shows overdues, this item must be treated as MISSED.
A32: E3 | B32: Other bureau red flags clarified | C32: Recent enquiries, settlement history, high utilisation — one question each, response noted. PLUS: “Kya aapne yeh file kisi aur bank ya NBFC mein bhi lagayi hai abhi?” — file simultaneously with another lender must surface here. | D32: BPS output | E32: — | F32: 4 | G32: None | H32: =IF(G32="N/A",0,F32*IF(G32="Full",1,IF(G32="Partial",0.5,0))) -> 0 | I32: No bureau red-flag questions and the mandatory 'file kisi aur bank/NBFC mein bhi lagayi hai?' question was never asked.
A33: SECTION F — COLLATERAL — BRIEF CHECK (window 9:00–10:00) | I33: 10
A34: F1 | B34: Property type, owner and location — in brief | C34: “Kaun si property girvi hogi — ghar/dukaan/plot? Kahan? Kiske naam par hai?” | D34: Application form | E34: — | F34: 5 | G34: Partial | H34: =IF(G34="N/A",0,F34*IF(G34="Full",1,IF(G34="Partial",0.5,0))) -> 2.5 | I34: 6:32–7:15 — property discussed: prior house (with running loan) sold last year; offered property probed for registry/sale-deed — but type/location/owner not pinned down clearly.
A35: F2 | B35: Willingness to mortgage + lien-free in brief | C35: “Property girvi rakhne mein koi dikkat? Us par koi aur loan/vivaad to nahi?” — reluctance or charge = FI-RF-7. | D35: Policy F.1; FI-RF-7 | E35: YES | F35: 5 | G35: Partial | H35: =IF(G35="N/A",0,F35*IF(G35="Full",1,IF(G35="Partial",0.5,0))) -> 2.5 | I35: Customer says 'uski registry nahin hai sir' (~6:45) — title/registry concern surfaced (FI-RF-7) but willingness-to-mortgage never explicitly asked and the issue was not resolved or escalated on call.
A36: SECTION G — CALL CONDUCT & BM DECISION (throughout + close) | I36: 10
A37: G1 | B37: Duration and quality (10–15 minutes) | C37: ≥ 10 min mandatory; ≤ 15; both sides audible/visible end-to-end; ≥90% intelligible. | D37: Gate K1 | E37: YES | F37: 3 | G37: None | H37: =IF(G37="N/A",0,F37*IF(G37="Full",1,IF(G37="Partial",0.5,0))) -> 0 | I37: Recording is 8 min 29 sec — below the MANDATORY 10-minute minimum (Gate K1). Audio intelligible but phone quality is rough in patches.
A38: G2 | B38: Open, non-leading questioning | C38: Amount, income, sourcing, obligations elicited openly; customer speaks first; no coaching. | D38: Gate K7 | E38: YES | F38: 3 | G38: Full | H38: =IF(G38="N/A",0,F38*IF(G38="Full",1,IF(G38="Partial",0.5,0))) -> 3 | I38: Amount (4:44), income (1:13–4:40), sourcing (0:26) and obligations (5:32) all elicited with open questions; customer speaks first; no third-party prompting audible; BM's arithmetic uses customer's own figures conservatively.
A39: G3 | B39: Clear BM decision recorded with reason | C39: FORWARD to CPA or REJECT at BM stage — with the specific reason. A well-reasoned rejection scores Full. On FORWARD, close by telling the customer the next steps: “Ab aapki file Credit Team ke paas jayegi — aapko Credit Department se call aayega, uske baad aapke business aur ghar ka visit hoga.” | D39: Process requirement | E39: — | F39: 4 | G39: None | H39: =IF(G39="N/A",0,F39*IF(G39="Full",1,IF(G39="Partial",0.5,0))) -> 0 | I39: Call ends abruptly ~8:16–8:29 with no FORWARD/REJECT decision, no reason, and no next-steps script (Credit call, business & home visit) to the customer.
B41: SECTION SUBTOTALS
B42: Section | C42: Max Pts | D42: Applicable Pts | E42: Scored | F42: Coverage %
...

Sheet Call Summary
A1: BM AUDIO/VIDEO FI — CALL SUMMARY FOR MANAGEMENT · Business Loan Against Property
A2: One-page digest of the FI call, filled by the Evaluator (AI Agent / Reviewer) so management need not hear the recording. The FI is a 10–15 minute genuineness & right-file check — NOT a PD — so this summary answers three management questions: Is the customer and file GENUINE? Is the sourcing CHANNEL clean? Is the file PRIMA FACIE eligible to go forward? Fill ONLY the yellow cells; checks, totals, score and verdict fill automatically. Every answer must come from what was actually SAID on the call — quote the timestamp; not asked/answered = write "Not covered".
A4: Application ID | C4: =IF(Scorecard!B2="","",Scorecard!B2) -> Not provided (application form not shared with evaluator) | E4: Score (/100) | G4: =IF(Scorecard!E61="","",Scorecard!E61) -> 49.5
A5: Customer Name | C5: =IF(Scorecard!B3="","",Scorecard!B3) -> Not clearly captured on audio (male borrower; dairy/milk-aggregation business, village near Biaora/Bhyavra) | E5: Grade Band | G5: =IF(Scorecard!E63="","",Scorecard!E63) -> D — Fail
A6: BM Name | C6: =IF(Scorecard!B4="","",Scorecard!B4) -> Lalit Gujar (self-introduced ~0:05, Prodigee Finance branch, Bhyavra/Biaora) | E6: Knock-Out Status | G6: =IF(Scorecard!E62="","",Scorecard!E62) -> FAILED — INVALID
A7: Date of FI Call | C7: =IF(Scorecard!B5="","",Scorecard!B5) -> 17-Aug-2026 (from recording file metadata) | E7: Final Verdict | G7: =IF(Scorecard!E64="","",Scorecard!E64) -> INVALID — RE-CONDUCT FI
A8: Loan Amount (Rs.) | C8: =IF(Scorecard!B7="","",Scorecard!B7) -> 800,000 (as stated by customer ~4:45; application amount not provided) | E8: Recording Duration (min) | G8: =IF(Scorecard!B6="","",Scorecard!B6) -> 8.5
A9: Auto-filled from the Scorecard sheet — do not type here. Grey cells show the evaluation outcome for this same FI call.
A11: CALL IN BRIEF — EXECUTIVE GIST (3–5 lines)
A12: Who the customer is · what he/she does · loan sought and purpose · how the file was sourced · what the FI established on genuineness, channel and eligibility · the BM's decision (FORWARD / REJECT) and why.
A13: Male borrower (name not clearly audible) from a village near Bhyavra/Biaora runs a milk-aggregation business — buys ~105 L/day in the village, adds ~15 L own milk from 5 buffaloes, and sells ~120 L to Krishna Milk Dairy at ~Rs.51/L for a Rs.3/L margin plus bonus, settled in cash. He seeks ~Rs.8 lakh (stated unprompted, ~4:45) to expand the dairy business; file sourced through 'Arjun' (Prodigee staff/RM) whom he has known ~2 years. One existing loan of ~Rs.3 lakh sits against a house he sold last year — he plans to close it from sale proceeds. The customer looks GENUINE, but the FI itself is INVALID: 8m29s (< 10-min mandatory), no recording disclosure, mortgage understanding never confirmed, agent/commission probes skipped, and the call ends with no BM decision. Property title is a live concern — customer says the offered property's registry is not available (~6:45).
A17: HEAD 1 — GENUINENESS & CUSTOMER AWARENESS (is this a real customer who really applied?)
A18: Spoke to MAIN BORROWER on video — face matches KYC photo? (YES / NO + timestamp) | C18: NO video — AUDIO-only recording; face-match vs KYC impossible. Voice/context indicates the main borrower himself (answers own file, business and loan details). Timestamp: throughout.
A19: Recording/video disclosure made at the start? (YES / NO) | C19: NO — no disclosure heard in the opening (0:00–1:00; verified on two ASR passes).
A20: Customer AWARE the application exists with Prodigee? (YES / NO → FI-RF-1 fraud referral) | C20: YES — confirms file with Prodigee Finance and names recipient 'Arjun' (0:05–0:52).
A21: Understands it is a BUSINESS loan with property MORTGAGED? (YES / NO — Gate K4) | C21: NO — property-backed loan discussed (6:32–7:15) but 'business loan + property MORTGAGED' never explicitly confirmed — Gate K4 not demonstrated.
A22: Loan amount STATED by customer (Rs.) — unprompted | C22: 800000
A23: Loan amount as per application (Rs.) | E23: =IF(OR(C23=0,C22=0),"— enter both amounts",IF(ABS(C22-C23)/C23<=0.1,"Within ±10% — Gate K5 OK","OUTSIDE ±10% → FI-RF-2 — reconcile with RM")) -> — enter both amounts
A24: End use stated by customer (business-linked? not restricted?) | C24: Expand/open dairy business (~4:50) — business-linked. Caution: end use touching milch-animal purchase is on the restricted list — was not probed.
A25: GENUINENESS VERDICT (GENUINE / DOUBTFUL / FRAUD SUSPECT) + why | C25: GENUINE (provisional) — aware of application, names the sourcing person, gives consistent granular business detail; no impersonation signs. Process gates failed, so re-conduct FI to certify.
A27: HEAD 2 — SOURCING & CHANNEL INTEGRITY (how did this file reach Prodigee?)
A28: How the loan reached the customer — RM name per customer; did the RM visit? (NO → FI-RF-8) | C28: Sourced through 'Arjun' — Prodigee staff/RM, known to customer ~2 years (0:26–1:00). RM visit to home/work NOT verified on call.
A29: Agent / broker / DSA / connector involved? (NONE / name & role → FI-RF-3, Gate K6) | C29: NOT PROBED — no agent/broker/DSA question asked. Nothing adverse surfaced spontaneously.
A30: Commission, fees or money demanded by anyone? (NO / details → FI-RF-4 — STOP, CCRO) | C30: NOT PROBED — zero-commission question never asked.
A31: Login fee — collected by whom, how much, receipt given? (non-RM collection → FI-RF-4) | C31: NOT PROBED — login-fee collection/receipt never asked.
A32: Sourcing story matches PRAGATI record? (YES / NO + what differs) | C32: CANNOT VERIFY — PRAGATI record not provided to evaluator. Story on call: RM-sourced via 2-year acquaintance.
A33: CHANNEL VERDICT (CLEAN / SUSPECT) + note | C33: CLEAN (provisional) — nothing adverse surfaced, but the three mandatory channel probes (agent, commission, login fee) were skipped; re-ask on the re-conducted FI.
A35: HEAD 3 — PRIMA FACIE ELIGIBILITY (income vs policy gates · bureau · collateral, in brief)
A36: FI-level check only — depth belongs to the BCM PD. Income streams as stated on the call, one row each; flag any stream the RM did NOT capture on PRAGATI.
A37: # | B37: Income stream (business / agri / dairy / rent / salary) | C37: Whose income (borrower / family member) | D37: Monthly amount stated (Rs.) | E37: Captured on PRAGATI by RM? (Yes / No) | F37: Timestamp | G37: Occupation vintage ≥ 1 yr? / on negative list? | H37: Remarks
A38: 1 | B38: Milk aggregation margin (dairy trading) | C38: Borrower | E38: Unknown — PRAGATI not provided | F38: 1:13–4:40 | G38: Asked (~4:55); answer partly garbled on audio | H38: ~105 L/day bought at village, sold to Krishna Milk Dairy; margin Rs.3/L + bonus => ~Rs.9,000–9,500/month derived (not stated as monthly on call)
A39: 2 | B39: Own milk sale (5 buffaloes) | C39: Borrower/household | E39: Unknown — PRAGATI not provided | F39: 1:38–2:02, 4:12 | G39: Same business | H39: ~15 L/day at ~Rs.51/L => ~Rs.22,000–23,000/month GROSS derived; feed/upkeep costs not netted on call
A40: 3 | B40: Agriculture land | C40: Father's name | E40: Unknown — PRAGATI not provided | F40: 2:03–2:26 | G40: Land asked: extent & owner; income not quantified | H40: No monthly figure stated
A41: 4 | B41: Brother's dairy work | C41: Brother | E41: Unknown — PRAGATI not provided | F41: 2:20–2:48 | G41: — | H41: Mentioned; not quantified
A42: 5
A43: TOTAL MONTHLY INCOME AS STATED ON CALL (Rs.) | D43: =SUM(D38:D42) -> 0 | E43: FI figures are as-stated, unverified — assessment happens at BCM PD stage
A44: HOUSEHOLD monthly income stated by customer (Rs.) | E44: =IF(C44=0,"— enter",IF(C44>=30000,"Policy gate ≥ ₹30,000 MET","BELOW ₹30,000 GATE → FI-RF-5 — REJECT at BM stage")) -> — enter
A45: Main earner's OWN monthly income stated (Rs.) | E45: =IF(C45=0,"— enter",IF(C45>=15000,"Policy gate ≥ ₹15,000 MET","BELOW ₹15,000 GATE → FI-RF-5 — REJECT at BM stage")) -> — enter
A46: Income streams NOT captured on PRAGATI by the RM (note for file, or "None") | C46: Agriculture (father's land) and brother's dairy work surfaced on call — check whether RM captured them on PRAGATI (record not provided). No monthly household figure was elicited — hence C44/C45 left blank; derived gross ~Rs.30–33k/month is BORDERLINE vs the Rs.30,000 gate.
A47: BM's prima facie sufficiency view as stated on call (sufficient / not sufficient + basis) | C47: No explicit sufficiency view stated on record; BM only worked the daily-saving arithmetic with the customer (3:35–4:40).
...

Sheet Gap & Coaching Report
A1: GAP & COACHING REPORT — what was missed in this FI (auto-generated from the Scorecard ratings)
A2: Fill the Coverage column on the Scorecard — every None/Partial item appears below with the exact question to ask next time. Clear list = 100. Target: 90+ on every FI.
A4: SCORE | B4: Total score (from Scorecard) | C4: =Scorecard!E61 -> 49.5
B5: Points still needed to reach 90+ (A-band, model FI) | C5: =IF(Scorecard!E61="","",MAX(0,ROUND(90-Scorecard!E61,1))) -> 40.5
A7: GATES | B7: Knock-out gates failed (each one alone makes the FI INVALID — re-conduct) | C7: Result
A8: =Scorecard!A53 -> K1 | B8: =IF(Scorecard!E53="FAIL","GATE FAILED — "&Scorecard!B53,"—") -> GATE FAILED — Valid recording exists — audible/visible both sides, materially complete, duration ≥ 10 minutes (MANDATORY) and not beyond 15 (target 10–12). | C8: =Scorecard!E53 -> FAIL
A9: =Scorecard!A54 -> K2 | B9: =IF(Scorecard!E54="FAIL","GATE FAILED — "&Scorecard!B54,"—") -> — | C9: =Scorecard!E54 -> PASS
A10: =Scorecard!A55 -> K3 | B10: =IF(Scorecard!E55="FAIL","GATE FAILED — "&Scorecard!B55,"—") -> GATE FAILED — Recording/video disclosure was made to the customer at the start of the call. | C10: =Scorecard!E55 -> FAIL
A11: =Scorecard!A56 -> K4 | B11: =IF(Scorecard!E56="FAIL","GATE FAILED — "&Scorecard!B56,"—") -> GATE FAILED — Customer clearly understands this is a BUSINESS Loan Against Property — property will be MORTGAGED. | C11: =Scorecard!E56 -> FAIL
A12: =Scorecard!A57 -> K5 | B12: =IF(Scorecard!E57="FAIL","GATE FAILED — "&Scorecard!B57,"—") -> — | C12: =Scorecard!E57 -> PASS
A13: =Scorecard!A58 -> K6 | B13: =IF(Scorecard!E58="FAIL","GATE FAILED — "&Scorecard!B58,"—") -> — | C13: =Scorecard!E58 -> PASS
A14: =Scorecard!A59 -> K7 | B14: =IF(Scorecard!E59="FAIL","GATE FAILED — "&Scorecard!B59,"—") -> — | C14: =Scorecard!E59 -> PASS
A16: ITEM | B16: WHAT WAS MISSED OR LEFT INCOMPLETE — cover this next time | C16: Points lost
A17: =Scorecard!A11 -> A1 | B17: =IF(Scorecard!G11="None","MISSED — "&Scorecard!B11&" | Ask: "&Scorecard!C11,IF(Scorecard!G11="Partial","INCOMPLETE — "&Scorecard!B11&" | Asked but not fully probed/confirmed.","")) -> MISSED — Recording/video disclosure made at the start of the call | Ask: “Yeh call/video recording par hai, aapke loan verification ke liye.” — within the first 60 seconds. | C17: =IF(Scorecard!G11="None",Scorecard!F11,IF(Scorecard!G11="Partial",Scorecard!F11/2,"")) -> 3
A18: =Scorecard!A12 -> A2 | B18: =IF(Scorecard!G12="None","MISSED — "&Scorecard!B12&" | Ask: "&Scorecard!C12,IF(Scorecard!G12="Partial","INCOMPLETE — "&Scorecard!B12&" | Asked but not fully probed/confirmed.","")) -> INCOMPLETE — Speaking to the MAIN BORROWER — video face verification | Asked but not fully probed/confirmed. | C18: =IF(Scorecard!G12="None",Scorecard!F12,IF(Scorecard!G12="Partial",Scorecard!F12/2,"")) -> 1.5
A19: =Scorecard!A13 -> A3 | B19: =IF(Scorecard!G13="None","MISSED — "&Scorecard!B13&" | Ask: "&Scorecard!C13,IF(Scorecard!G13="Partial","INCOMPLETE — "&Scorecard!B13&" | Asked but not fully probed/confirmed.","")) | C19: =IF(Scorecard!G13="None",Scorecard!F13,IF(Scorecard!G13="Partial",Scorecard!F13/2,""))
A20: =Scorecard!A14 -> A4 | B20: =IF(Scorecard!G14="None","MISSED — "&Scorecard!B14&" | Ask: "&Scorecard!C14,IF(Scorecard!G14="Partial","INCOMPLETE — "&Scorecard!B14&" | Asked but not fully probed/confirmed.","")) | C20: =IF(Scorecard!G14="None",Scorecard!F14,IF(Scorecard!G14="Partial",Scorecard!F14/2,""))
A21: =Scorecard!A16 -> B1 | B21: =IF(Scorecard!G16="None","MISSED — "&Scorecard!B16&" | Ask: "&Scorecard!C16,IF(Scorecard!G16="Partial","INCOMPLETE — "&Scorecard!B16&" | Asked but not fully probed/confirmed.","")) -> INCOMPLETE — RM visit verified — who sourced and visited | Asked but not fully probed/confirmed. | C21: =IF(Scorecard!G16="None",Scorecard!F16,IF(Scorecard!G16="Partial",Scorecard!F16/2,"")) -> 2
A22: =Scorecard!A17 -> B2 | B22: =IF(Scorecard!G17="None","MISSED — "&Scorecard!B17&" | Ask: "&Scorecard!C17,IF(Scorecard!G17="Partial","INCOMPLETE — "&Scorecard!B17&" | Asked but not fully probed/confirmed.","")) -> MISSED — Agent / broker / DSA involvement probed | Ask: “Beech mein koi agent, broker, DSA, connector ya sales agent hai? Kisi ne file lagwane mein madad ki — kaun?” — undisclosed middleman = FI-RF-3 / Gate K6. | C22: =IF(Scorecard!G17="None",Scorecard!F17,IF(Scorecard!G17="Partial",Scorecard!F17/2,"")) -> 4
A23: =Scorecard!A18 -> B3 | B23: =IF(Scorecard!G18="None","MISSED — "&Scorecard!B18&" | Ask: "&Scorecard!C18,IF(Scorecard!G18="Partial","INCOMPLETE — "&Scorecard!B18&" | Asked but not fully probed/confirmed.","")) -> MISSED — Zero-commission integrity check | Ask: “Kya kisi ne is loan ke liye aapse commission, fees ya paisa manga hai? Prodigee mein ZERO COMMISSION policy hai.” PLUS login fee: “Login fee kisne collect ki — Prodigee ke RM ne hi? Kitni di? Receipt mili?” — fee collected by anyone other than the RM = FI-RF-4. Demand = FI-RF-4 (STOP — CCRO). | C23: =IF(Scorecard!G18="None",Scorecard!F18,IF(Scorecard!G18="Partial",Scorecard!F18/2,"")) -> 4
A24: =Scorecard!A19 -> B4 | B24: =IF(Scorecard!G19="None","MISSED — "&Scorecard!B19&" | Ask: "&Scorecard!C19,IF(Scorecard!G19="Partial","INCOMPLETE — "&Scorecard!B19&" | Asked but not fully probed/confirmed.","")) -> INCOMPLETE — Sourcing story consistent with PRAGATI | Asked but not fully probed/confirmed. | C24: =IF(Scorecard!G19="None",Scorecard!F19,IF(Scorecard!G19="Partial",Scorecard!F19/2,"")) -> 2
A25: =Scorecard!A21 -> C1 | B25: =IF(Scorecard!G21="None","MISSED — "&Scorecard!B21&" | Ask: "&Scorecard!C21,IF(Scorecard!G21="Partial","INCOMPLETE — "&Scorecard!B21&" | Asked but not fully probed/confirmed.","")) -> INCOMPLETE — Knows it is a BUSINESS Loan Against Property — mortgage | Asked but not fully probed/confirmed. | C25: =IF(Scorecard!G21="None",Scorecard!F21,IF(Scorecard!G21="Partial",Scorecard!F21/2,"")) -> 2
A26: =Scorecard!A22 -> C2 | B26: =IF(Scorecard!G22="None","MISSED — "&Scorecard!B22&" | Ask: "&Scorecard!C22,IF(Scorecard!G22="Partial","INCOMPLETE — "&Scorecard!B22&" | Asked but not fully probed/confirmed.","")) -> INCOMPLETE — Loan amount stated by the customer | Asked but not fully probed/confirmed. | C26: =IF(Scorecard!G22="None",Scorecard!F22,IF(Scorecard!G22="Partial",Scorecard!F22/2,"")) -> 2
A27: =Scorecard!A23 -> C3 | B27: =IF(Scorecard!G23="None","MISSED — "&Scorecard!B23&" | Ask: "&Scorecard!C23,IF(Scorecard!G23="Partial","INCOMPLETE — "&Scorecard!B23&" | Asked but not fully probed/confirmed.","")) -> INCOMPLETE — End use understood in brief | Asked but not fully probed/confirmed. | C27: =IF(Scorecard!G23="None",Scorecard!F23,IF(Scorecard!G23="Partial",Scorecard!F23/2,"")) -> 2
A28: =Scorecard!A25 -> D1 | B28: =IF(Scorecard!G25="None","MISSED — "&Scorecard!B25&" | Ask: "&Scorecard!C25,IF(Scorecard!G25="Partial","INCOMPLETE — "&Scorecard!B25&" | Asked but not fully probed/confirmed.","")) | C28: =IF(Scorecard!G25="None",Scorecard!F25,IF(Scorecard!G25="Partial",Scorecard!F25/2,""))
A29: =Scorecard!A26 -> D2 | B29: =IF(Scorecard!G26="None","MISSED — "&Scorecard!B26&" | Ask: "&Scorecard!C26,IF(Scorecard!G26="Partial","INCOMPLETE — "&Scorecard!B26&" | Asked but not fully probed/confirmed.","")) -> INCOMPLETE — Income tested against policy gates | Asked but not fully probed/confirmed. | C29: =IF(Scorecard!G26="None",Scorecard!F26,IF(Scorecard!G26="Partial",Scorecard!F26/2,"")) -> 3
A30: =Scorecard!A27 -> D3 | B30: =IF(Scorecard!G27="None","MISSED — "&Scorecard!B27&" | Ask: "&Scorecard!C27,IF(Scorecard!G27="Partial","INCOMPLETE — "&Scorecard!B27&" | Asked but not fully probed/confirmed.","")) | C30: =IF(Scorecard!G27="None",Scorecard!F27,IF(Scorecard!G27="Partial",Scorecard!F27/2,""))
A31: =Scorecard!A28 -> D4 | B31: =IF(Scorecard!G28="None","MISSED — "&Scorecard!B28&" | Ask: "&Scorecard!C28,IF(Scorecard!G28="Partial","INCOMPLETE — "&Scorecard!B28&" | Asked but not fully probed/confirmed.","")) -> INCOMPLETE — BM's sufficiency view formed | Asked but not fully probed/confirmed. | C31: =IF(Scorecard!G28="None",Scorecard!F28,IF(Scorecard!G28="Partial",Scorecard!F28/2,"")) -> 3
A32: =Scorecard!A30 -> E1 | B32: =IF(Scorecard!G30="None","MISSED — "&Scorecard!B30&" | Ask: "&Scorecard!C30,IF(Scorecard!G30="Partial","INCOMPLETE — "&Scorecard!B30&" | Asked but not fully probed/confirmed.","")) -> INCOMPLETE — Running loans acknowledged vs BPS/bureau | Asked but not fully probed/confirmed. | C32: =IF(Scorecard!G30="None",Scorecard!F30,IF(Scorecard!G30="Partial",Scorecard!F30/2,"")) -> 3
A33: =Scorecard!A31 -> E2 | B33: =IF(Scorecard!G31="None","MISSED — "&Scorecard!B31&" | Ask: "&Scorecard!C31,IF(Scorecard!G31="Partial","INCOMPLETE — "&Scorecard!B31&" | Asked but not fully probed/confirmed.","")) | C33: =IF(Scorecard!G31="None",Scorecard!F31,IF(Scorecard!G31="Partial",Scorecard!F31/2,""))
A34: =Scorecard!A32 -> E3 | B34: =IF(Scorecard!G32="None","MISSED — "&Scorecard!B32&" | Ask: "&Scorecard!C32,IF(Scorecard!G32="Partial","INCOMPLETE — "&Scorecard!B32&" | Asked but not fully probed/confirmed.","")) -> MISSED — Other bureau red flags clarified | Ask: Recent enquiries, settlement history, high utilisation — one question each, response noted. PLUS: “Kya aapne yeh file kisi aur bank ya NBFC mein bhi lagayi hai abhi?” — file simultaneously with another lender must surface here. | C34: =IF(Scorecard!G32="None",Scorecard!F32,IF(Scorecard!G32="Partial",Scorecard!F32/2,"")) -> 4
A35: =Scorecard!A34 -> F1 | B35: =IF(Scorecard!G34="None","MISSED — "&Scorecard!B34&" | Ask: "&Scorecard!C34,IF(Scorecard!G34="Partial","INCOMPLETE — "&Scorecard!B34&" | Asked but not fully probed/confirmed.","")) -> INCOMPLETE — Property type, owner and location — in brief | Asked but not fully probed/confirmed. | C35: =IF(Scorecard!G34="None",Scorecard!F34,IF(Scorecard!G34="Partial",Scorecard!F34/2,"")) -> 2.5
A36: =Scorecard!A35 -> F2 | B36: =IF(Scorecard!G35="None","MISSED — "&Scorecard!B35&" | Ask: "&Scorecard!C35,IF(Scorecard!G35="Partial","INCOMPLETE — "&Scorecard!B35&" | Asked but not fully probed/confirmed.","")) -> INCOMPLETE — Willingness to mortgage + lien-free in brief | Asked but not fully probed/confirmed. | C36: =IF(Scorecard!G35="None",Scorecard!F35,IF(Scorecard!G35="Partial",Scorecard!F35/2,"")) -> 2.5
A37: =Scorecard!A37 -> G1 | B37: =IF(Scorecard!G37="None","MISSED — "&Scorecard!B37&" | Ask: "&Scorecard!C37,IF(Scorecard!G37="Partial","INCOMPLETE — "&Scorecard!B37&" | Asked but not fully probed/confirmed.","")) -> MISSED — Duration and quality (10–15 minutes) | Ask: ≥ 10 min mandatory; ≤ 15; both sides audible/visible end-to-end; ≥90% intelligible. | C37: =IF(Scorecard!G37="None",Scorecard!F37,IF(Scorecard!G37="Partial",Scorecard!F37/2,"")) -> 3
A38: =Scorecard!A38 -> G2 | B38: =IF(Scorecard!G38="None","MISSED — "&Scorecard!B38&" | Ask: "&Scorecard!C38,IF(Scorecard!G38="Partial","INCOMPLETE — "&Scorecard!B38&" | Asked but not fully probed/confirmed.","")) | C38: =IF(Scorecard!G38="None",Scorecard!F38,IF(Scorecard!G38="Partial",Scorecard!F38/2,""))
A39: =Scorecard!A39 -> G3 | B39: =IF(Scorecard!G39="None","MISSED — "&Scorecard!B39&" | Ask: "&Scorecard!C39,IF(Scorecard!G39="Partial","INCOMPLETE — "&Scorecard!B39&" | Asked but not fully probed/confirmed.","")) -> MISSED — Clear BM decision recorded with reason | Ask: FORWARD to CPA or REJECT at BM stage — with the specific reason. A well-reasoned rejection scores Full. On FORWARD, close by telling the customer the next steps: “Ab aapki file Credit Team ke paas jayegi — aapko Credit Department se call aayega, uske baad aapke business aur ghar ka visit hoga.” | C39: =IF(Scorecard!G39="None",Scorecard!F39,IF(Scorecard!G39="Partial",Scorecard!F39/2,"")) -> 4
B40: TOTAL POINTS LOST to missed / incomplete items | C40: =SUM(C17:C39) -> 47.5

Sheet Reference Lists
A1: RED FLAGS — MANDATORY ESCALATION TRIGGERS (BM FI)
A3: Code | B3: Trigger detected on the call | C3: Required action
A4: FI-RF-1 | B4: Customer unaware that a loan application exists or does not know Prodigee. | C4: STOP — refer RCU & CCRO (possible fraud)
A5: FI-RF-2 | B5: Loan amount stated differs from the application by more than ±10%. | C5: Reconcile with RM before forwarding
A6: FI-RF-3 | B6: Agent / broker / DSA involvement surfaced in sourcing. | C6: STOP — CCRO; channel integrity review
A7: FI-RF-4 | B7: Anyone demanded commission, fees or money from the customer. | C7: STOP — CCRO + HR/conduct referral (Zero Commission Policy)
A8: FI-RF-5 | B8: Income below policy gates (household < ₹30,000/month or no earner ≥ ₹15,000). | C8: REJECT at BM stage with reason — do not forward to CPA
A9: FI-RF-6 | B9: Overdue/bounce on BPS unexplained or denied; or loan disclosed that bureau does not show. | C9: Reject or hold; escalate to RCM/CCRO if forwarded
A10: FI-RF-7 | B10: Customer reluctant to mortgage, or existing charge/dispute on the property. | C10: Hold — resolve before CPA; Legal referral if charge exists
A11: FI-RF-8 | B11: RM never visited the customer / sourcing story contradicts PRAGATI. | C11: Return to RM; sourcing-integrity note to CCRO
A13: SCORE BANDS & ACTIONS
A14: Score | B14: Band | C14: Action
A15: 90–100 | B15: A — Excellent | C15: Model FI. Forward per BM decision; training library.
A16: 75–89 | B16: B — Pass | C16: FI acceptable. BM decision (forward/reject) stands.
A17: 60–74 | B17: C — Conditional | C17: Supplementary call covering missed items before CPA.
A18: Below 60 | B18: D — Fail | C18: FI re-conducted in full; counts in BM quality MIS.
A19: Any knock-out failed | B19: INVALID | C19: Recording rejected regardless of score; re-conduct.
A21: Minimum passing standard: Score ≥ 75 AND all 7 knock-out gates PASS AND no open red flag.
