Workbook

Sheet Scorecard
A1: BCM PHYSICAL PD — AUDIO RECORDING SCORECARD (V2.1 Simple)
A2: Evaluator: fill the yellow cells only. For each item choose Yes (fully said with names/numbers), Half (mentioned but vague/incomplete) or No (not said). If the BCM clearly says something does NOT exist (no land, no dairy, no other income, no defaults, no enquiries) — that IS covered: mark YES. Score, result and the BCM's "My Result" page fill automatically.
A4: Application ID | C4: Recording length (minutes)
A5: Customer name | C5: Recorded same day as visits? (Yes/No)
A6: BCM name | C6: Farm / dairy / other family income in this case? (Yes/No — for record only; Group C is always scored)
A7: Date of PD & recording | C7: Evaluator
A9: No | B9: WHAT THE BCM MUST SAY IN THE RECORDING | C9: Points | D9: MUST | E9: Covered? (Yes / Half / No) | F9: Score | G9: What was missing — evaluator note | H9: lost (helper)
A10: A. VISIT & PHOTOS | C10: 10 | G10: Minute 0–2
A11: A1 | B11: Start with: Application ID, customer name, village/town, loan amount asked. Say that you checked the CRIF report and BPS score before going. | C11: 2 | F11: =IF(E11="Yes",C11,IF(E11="Half",C11/2,0)) -> 0 | H11: =IF(E11="Yes",0,IF(E11="Half",C11/2,C11))+IF(E11="Yes",0,(1000-ROW())/100000) -> 2.00989
A12: A2 | B12: Say that you met the BORROWER HIMSELF at his business — not on phone, not through a relative. Date, time, and who came with you. | C12: 2 | D12: MUST | F12: =IF(E12="Yes",C12,IF(E12="Half",C12/2,0)) -> 0 | H12: =IF(E12="Yes",0,IF(E12="Half",C12/2,C12))+IF(E12="Yes",0,(1000-ROW())/100000) -> 2.00988
A13: A3 | B13: Time spent: business (start–end) and home (start–end). Total must be at least 1 hour (normally 1 to 1.5 hours). | C13: 2 | F13: =IF(E13="Yes",C13,IF(E13="Half",C13/2,0)) -> 0 | H13: =IF(E13="Yes",0,IF(E13="Half",C13/2,C13))+IF(E13="Yes",0,(1000-ROW())/100000) -> 2.00987
A14: A4 | B14: Home and property visited (say if home and property are the same house). Co-borrower and family met at home. | C14: 2 | F14: =IF(E14="Yes",C14,IF(E14="Half",C14/2,0)) -> 0 | H14: =IF(E14="Yes",0,IF(E14="Half",C14/2,C14))+IF(E14="Yes",0,(1000-ROW())/100000) -> 2.00986
A15: A5 | B15: Photos taken and uploaded: signboard, QR code, FULL stock, purchase bills, sales bills / register / khata, mandi receipts, every room of the house, household items, electricity meter, both business neighbours, both home neighbours, land / animals (if any), property papers. | C15: 2 | F15: =IF(E15="Yes",C15,IF(E15="Half",C15/2,0)) -> 0 | H15: =IF(E15="Yes",0,IF(E15="Half",C15/2,C15))+IF(E15="Yes",0,(1000-ROW())/100000) -> 2.00985
A16: B. BUSINESS (say this for EVERY business — borrower's and family members') | C16: 30 | G16: Minute 2–9
A17: B1 | B17: What you SAW: shop/unit size, how much stock, how many staff, customers during your visit, machines, signboard. Every business visited — including one run by wife, son, father. | C17: 3 | D17: MUST | F17: =IF(E17="Yes",C17,IF(E17="Half",C17/2,0)) -> 0 | H17: =IF(E17="Yes",0,IF(E17="Half",C17/2,C17))+IF(E17="Yes",0,(1000-ROW())/100000) -> 3.00983
A18: B2 | B18: Who actually runs it; running since which year; what the borrower did BEFORE this; new business or family business for generations; shop owned or rented (rent, years here); licence seen (Udyam / Gumasta / GST / FSSAI). | C18: 3 | F18: =IF(E18="Yes",C18,IF(E18="Half",C18/2,0)) -> 0 | H18: =IF(E18="Yes",0,IF(E18="Half",C18/2,C18))+IF(E18="Yes",0,(1000-ROW())/100000) -> 3.00982
A19: B3 | B19: PURCHASES: buys material from where; purchase bills of last 12 months seen?; % paid by bank/UPI and % by cash; TOP 5 SUPPLIERS with names and mobile numbers; credit taken from suppliers (days, amount due). | C19: 4 | F19: =IF(E19="Yes",C19,IF(E19="Half",C19/2,0)) -> 0 | H19: =IF(E19="Yes",0,IF(E19="Half",C19/2,C19))+IF(E19="Yes",0,(1000-ROW())/100000) -> 4.00981
A20: B4 | B20: SALES: who buys; % received in cash and % by UPI; QR code / UPI is in WHOSE name; sales today and average daily sales; average monthly sales; lean months and daily sales in lean months; udhaar (credit) given to customers — how much. | C20: 4 | F20: =IF(E20="Yes",C20,IF(E20="Half",C20/2,0)) -> 0 | H20: =IF(E20="Yes",0,IF(E20="Half",C20/2,C20))+IF(E20="Yes",0,(1000-ROW())/100000) -> 4.0098
A21: B5 | B21: STOCK: you counted the stock yourself — your value (Rs.) vs what the customer says. | C21: 2 | F21: =IF(E21="Yes",C21,IF(E21="Half",C21/2,0)) -> 0 | H21: =IF(E21="Yes",0,IF(E21="Half",C21/2,C21))+IF(E21="Yes",0,(1000-ROW())/100000) -> 2.00979
A22: B6 | B22: INCOME — BALL-PARK only (no detailed maths needed at PD): (1) what the CUSTOMER says his monthly income from the business is, and (2) what YOU think the monthly income is, as a rough figure. Both numbers must be said. | C22: 4 | F22: =IF(E22="Yes",C22,IF(E22="Half",C22/2,0)) -> 0 | H22: =IF(E22="Yes",0,IF(E22="Half",C22/2,C22))+IF(E22="Yes",0,(1000-ROW())/100000) -> 4.00978
A23: B7 | B23: AA (Account Aggregator) triggered on PRAGATI for ALL bank accounts of borrower and co-borrowers — name each account and say SUCCESS or FAILED for each. Documents seen: bills, register, khata, passbook, kata parchi. | C23: 3 | D23: MUST | F23: =IF(E23="Yes",C23,IF(E23="Half",C23/2,0)) -> 0 | H23: =IF(E23="Yes",0,IF(E23="Half",C23/2,C23))+IF(E23="Yes",0,(1000-ROW())/100000) -> 3.00977
A24: B8 | B24: 2 BUSINESS NEIGHBOURS: name, shop, mobile number, how long this business is running here, what they said about the customer. Photos taken. | C24: 4 | D24: MUST | F24: =IF(E24="Yes",C24,IF(E24="Half",C24/2,0)) -> 0 | H24: =IF(E24="Yes",0,IF(E24="Half",C24/2,C24))+IF(E24="Yes",0,(1000-ROW())/100000) -> 4.00976
A25: B9 | B25: YOUR VIEW on each business: genuine and running — or doubt (borrowed stock, arranged setup, too small for the claim). Say it clearly. | C25: 3 | F25: =IF(E25="Yes",C25,IF(E25="Half",C25/2,0)) -> 0 | H25: =IF(E25="Yes",0,IF(E25="Half",C25/2,C25))+IF(E25="Yes",0,(1000-ROW())/100000) -> 3.00975
A26: C. FARM, DAIRY & OTHER FAMILY INCOME (ALWAYS scored — if there is no land / dairy / other income, the BCM must SAY SO clearly: that gets FULL points) | C26: 10 | G26: Minute 9–11
A27: C1 | B27: LAND: is there agriculture land — YES or NO? If NO land, and the BCM says so clearly → mark YES (full points; no Khasra / land details needed). If land is there: how many acres, in whose name, and does the family cultivate it themselves or give it to someone else. | C27: 3 | F27: =IF(E27="Yes",C27,IF(E27="Half",C27/2,0)) -> 0 | H27: =IF(E27="Yes",0,IF(E27="Half",C27/2,C27))+IF(E27="Yes",0,(1000-ROW())/100000) -> 3.00973
A28: C2 | B28: CROPS: how many crops a year, and the profit per season after all expenses. If the BCM has said there is NO land → mark YES (full points). | C28: 3 | F28: =IF(E28="Yes",C28,IF(E28="Half",C28/2,0)) -> 0 | H28: =IF(E28="Yes",0,IF(E28="Half",C28/2,C28))+IF(E28="Yes",0,(1000-ROW())/100000) -> 3.00972
A29: C3 | B29: DAIRY: any dairy animals — YES or NO? If yes: how many are milking, litres of milk per day sold, and where it is sold. If the BCM says clearly there are NO dairy animals → mark YES (full points). | C29: 2 | F29: =IF(E29="Yes",C29,IF(E29="Half",C29/2,0)) -> 0 | H29: =IF(E29="Yes",0,IF(E29="Half",C29/2,C29))+IF(E29="Yes",0,(1000-ROW())/100000) -> 2.00971
A30: C4 | B30: OTHER INCOME of the WHOLE FAMILY (other than the main business, farm and dairy): each source of income, who in the family earns it, and any proof available. If there is no other income and the BCM says so clearly → mark YES (full points). | C30: 2 | F30: =IF(E30="Yes",C30,IF(E30="Half",C30/2,0)) -> 0 | H30: =IF(E30="Yes",0,IF(E30="Half",C30/2,C30))+IF(E30="Yes",0,(1000-ROW())/100000) -> 2.0097
A31: D. LOANS & REPAYMENT | C31: 12 | G31: Minute 11–14
A32: D1 | B32: All ACTIVE loans in the CRIF of borrower and co-borrowers — lender, EMI, outstanding — discussed with the customer. Closed loans need NOT be discussed. | C32: 4 | D32: MUST | F32: =IF(E32="Yes",C32,IF(E32="Half",C32/2,0)) -> 0 | H32: =IF(E32="Yes",0,IF(E32="Half",C32/2,C32))+IF(E32="Yes",0,(1000-ROW())/100000) -> 4.00968
A33: D2 | B33: DEFAULTS: loans defaulted in the PAST — with the reason; and any loan in default NOW — with the reason. If there are no defaults, the BCM says so clearly → mark YES. | C33: 3 | F33: =IF(E33="Yes",C33,IF(E33="Half",C33/2,0)) -> 0 | H33: =IF(E33="Yes",0,IF(E33="Half",C33/2,C33))+IF(E33="Yes",0,(1000-ROW())/100000) -> 3.00967
A34: D3 | B34: Approximate family expenses per month (overall figure is enough). School fees may or may not be mentioned. Next-12-month expenses NOT needed. | C34: 2 | F34: =IF(E34="Yes",C34,IF(E34="Half",C34/2,0)) -> 0 | H34: =IF(E34="Yes",0,IF(E34="Half",C34/2,C34))+IF(E34="Yes",0,(1000-ROW())/100000) -> 2.00966
A35: D4 | B35: ENQUIRIES in the last 3 months (from CRIF): how many, and for each — current status, sanctioned or not; if not sanctioned, the reason. If there are no enquiries, the BCM says so clearly → mark YES. | C35: 3 | F35: =IF(E35="Yes",C35,IF(E35="Half",C35/2,0)) -> 0 | H35: =IF(E35="Yes",0,IF(E35="Half",C35/2,C35))+IF(E35="Yes",0,(1000-ROW())/100000) -> 3.00965
A36: E. FAMILY & HOME | C36: 12 | G36: Minute 14–17
A37: E1 | B37: HOME: own or rented, years living here, pucca / kachha, rooms; electricity bill in whose name; items seen — tractor, car, bike, TV, fridge, washing machine, smartphones (how many), cooler / AC, gas, electricity meter. Does the standard of living match the income claimed? | C37: 3 | F37: =IF(E37="Yes",C37,IF(E37="Half",C37/2,0)) -> 0 | H37: =IF(E37="Yes",0,IF(E37="Half",C37/2,C37))+IF(E37="Yes",0,(1000-ROW())/100000) -> 3.00963
A38: E2 | B38: CO-BORROWERS met in person and aware of the loan. KYC IDs (Aadhaar / PAN / Voter / Samagra) of the borrower and ALL co-borrowers checked. Other family members need not be met, but each one must be noted: name, age and what they do. | C38: 4 | D38: MUST | F38: =IF(E38="Yes",C38,IF(E38="Half",C38/2,0)) -> 0 | H38: =IF(E38="Yes",0,IF(E38="Half",C38/2,C38))+IF(E38="Yes",0,(1000-ROW())/100000) -> 4.00962
A39: E3 | B39: 2 HOME NEIGHBOURS: name, mobile number, how long the family is staying here, conduct, any dispute. Photos taken. | C39: 3 | D39: MUST | F39: =IF(E39="Yes",C39,IF(E39="Half",C39/2,0)) -> 0 | H39: =IF(E39="Yes",0,IF(E39="Half",C39/2,C39))+IF(E39="Yes",0,(1000-ROW())/100000) -> 3.00961
A40: E4 | B40: Told the customer and family: this is a Loan Against Property (house mortgaged), the EMI amount, Clean Track Reward (last 3 EMIs waived on clean repayment), ZERO COMMISSION — pay nobody, Prodigee works on trust and integrity. | C40: 2 | F40: =IF(E40="Yes",C40,IF(E40="Half",C40/2,0)) -> 0 | H40: =IF(E40="Yes",0,IF(E40="Half",C40/2,C40))+IF(E40="Yes",0,(1000-ROW())/100000) -> 2.0096
A41: F. PROPERTY | C41: 14 | G41: Minute 17–20
A42: F1 | B42: Property: house / shop / plot, self-occupied or rented out, pucca, age, area (sq.ft), road access, kitchen and toilet, condition. | C42: 3 | F42: =IF(E42="Yes",C42,IF(E42="Half",C42/2,0)) -> 0 | H42: =IF(E42="Yes",0,IF(E42="Half",C42/2,C42))+IF(E42="Yes",0,(1000-ROW())/100000) -> 3.00958
...

Sheet My Result
A1: MY PD AUDIO RESULT
A2: Read this after every recording. It shows your score, what you missed and what to cover first next time. Nothing to fill here — it comes from the Scorecard.
A4: BCM | C4: =Scorecard!B6 -> 0
A5: Customer | C5: =Scorecard!B5 -> 0
A6: Application ID | C6: =Scorecard!B4 -> 0
A7: Date | C7: =Scorecard!B7 -> 0
A8: Recording length (min) | C8: =Scorecard!E4 -> 0
A10: MY SCORE | C10: =Scorecard!C56&" / 100" -> 0 / 100
A11: RESULT | C11: =Scorecard!C59 -> NOT ACCEPTED — recording under 15 min / over 25 min / not same day. Record again.
A12: Minimum to pass: 75. All MUST items must be Yes. 90+ is Excellent.
B14: HOW I DID — GROUP-WISE | C14: Points | D14: I got | E14: % | F14: Comment
A15: A | B15: Visit & Photos | C15: 10 | D15: =IF(C15="N/A","N/A",SUM(Scorecard!F11:F15)) -> 0 | E15: =IF(C15="N/A","N/A",ROUND(D15/C15*100,0)&"%") -> 0% | F15: =IF(C15="N/A","Not applicable in this case",IF(D15=C15,"Fully covered",IF(D15>=C15*0.75,"Good — small gaps",IF(D15>=C15*0.5,"Weak — see items below","Mostly missed — see items below")))) -> Mostly missed — see items below
A16: B | B16: Business | C16: 30 | D16: =IF(C16="N/A","N/A",SUM(Scorecard!F17:F25)) -> 0 | E16: =IF(C16="N/A","N/A",ROUND(D16/C16*100,0)&"%") -> 0% | F16: =IF(C16="N/A","Not applicable in this case",IF(D16=C16,"Fully covered",IF(D16>=C16*0.75,"Good — small gaps",IF(D16>=C16*0.5,"Weak — see items below","Mostly missed — see items below")))) -> Mostly missed — see items below
A17: C | B17: Farm, Dairy & Other Family Income | C17: 10 | D17: =IF(C17="N/A","N/A",SUM(Scorecard!F27:F30)) -> 0 | E17: =IF(C17="N/A","N/A",ROUND(D17/C17*100,0)&"%") -> 0% | F17: =IF(C17="N/A","Not applicable in this case",IF(D17=C17,"Fully covered",IF(D17>=C17*0.75,"Good — small gaps",IF(D17>=C17*0.5,"Weak — see items below","Mostly missed — see items below")))) -> Mostly missed — see items below
A18: D | B18: Loans & Repayment | C18: 12 | D18: =IF(C18="N/A","N/A",SUM(Scorecard!F32:F35)) -> 0 | E18: =IF(C18="N/A","N/A",ROUND(D18/C18*100,0)&"%") -> 0% | F18: =IF(C18="N/A","Not applicable in this case",IF(D18=C18,"Fully covered",IF(D18>=C18*0.75,"Good — small gaps",IF(D18>=C18*0.5,"Weak — see items below","Mostly missed — see items below")))) -> Mostly missed — see items below
A19: E | B19: Family & Home | C19: 12 | D19: =IF(C19="N/A","N/A",SUM(Scorecard!F37:F40)) -> 0 | E19: =IF(C19="N/A","N/A",ROUND(D19/C19*100,0)&"%") -> 0% | F19: =IF(C19="N/A","Not applicable in this case",IF(D19=C19,"Fully covered",IF(D19>=C19*0.75,"Good — small gaps",IF(D19>=C19*0.5,"Weak — see items below","Mostly missed — see items below")))) -> Mostly missed — see items below
A20: F | B20: Property | C20: 14 | D20: =IF(C20="N/A","N/A",SUM(Scorecard!F42:F46)) -> 0 | E20: =IF(C20="N/A","N/A",ROUND(D20/C20*100,0)&"%") -> 0% | F20: =IF(C20="N/A","Not applicable in this case",IF(D20=C20,"Fully covered",IF(D20>=C20*0.75,"Good — small gaps",IF(D20>=C20*0.5,"Weak — see items below","Mostly missed — see items below")))) -> Mostly missed — see items below
A21: G | B21: Loan Purpose & Your View | C21: 12 | D21: =IF(C21="N/A","N/A",SUM(Scorecard!F48:F51)) -> 0 | E21: =IF(C21="N/A","N/A",ROUND(D21/C21*100,0)&"%") -> 0% | F21: =IF(C21="N/A","Not applicable in this case",IF(D21=C21,"Fully covered",IF(D21>=C21*0.75,"Good — small gaps",IF(D21>=C21*0.5,"Weak — see items below","Mostly missed — see items below")))) -> Mostly missed — see items below
A23: NEXT TIME — COVER THESE FIRST (the 3 items where I lost most points)
A24: 1 | B24: =IF(LARGE(Scorecard!$H$11:$H$51,1)<0.5,"—",INDEX(Scorecard!$A$11:$A$51,MATCH(LARGE(Scorecard!$H$11:$H$51,1),Scorecard!$H$11:$H$51,0))&" — "&INDEX(Scorecard!$B$11:$B$51,MATCH(LARGE(Scorecard!$H$11:$H$51,1),Scorecard!$H$11:$H$51,0))) -> B3 — PURCHASES: buys material from where; purchase bills of last 12 months seen?; % paid by bank/UPI and % by cash; TOP 5 SUPPLIERS with names and mobile numbers; credit taken from suppliers (days, amount due). | F24: =IF(LARGE(Scorecard!$H$11:$H$51,1)<0.5,"", "Points lost: "&ROUND(LARGE(Scorecard!$H$11:$H$51,1),1)) -> Points lost: 4
A25: 2 | B25: =IF(LARGE(Scorecard!$H$11:$H$51,2)<0.5,"—",INDEX(Scorecard!$A$11:$A$51,MATCH(LARGE(Scorecard!$H$11:$H$51,2),Scorecard!$H$11:$H$51,0))&" — "&INDEX(Scorecard!$B$11:$B$51,MATCH(LARGE(Scorecard!$H$11:$H$51,2),Scorecard!$H$11:$H$51,0))) -> B4 — SALES: who buys; % received in cash and % by UPI; QR code / UPI is in WHOSE name; sales today and average daily sales; average monthly sales; lean months and daily sales in lean months; udhaar (credit) given to customers — how much. | F25: =IF(LARGE(Scorecard!$H$11:$H$51,2)<0.5,"", "Points lost: "&ROUND(LARGE(Scorecard!$H$11:$H$51,2),1)) -> Points lost: 4
A26: 3 | B26: =IF(LARGE(Scorecard!$H$11:$H$51,3)<0.5,"—",INDEX(Scorecard!$A$11:$A$51,MATCH(LARGE(Scorecard!$H$11:$H$51,3),Scorecard!$H$11:$H$51,0))&" — "&INDEX(Scorecard!$B$11:$B$51,MATCH(LARGE(Scorecard!$H$11:$H$51,3),Scorecard!$H$11:$H$51,0))) -> B6 — INCOME — BALL-PARK only (no detailed maths needed at PD): (1) what the CUSTOMER says his monthly income from the business is, and (2) what YOU think the monthly income is, as a rough figure. Both numbers must be said. | F26: =IF(LARGE(Scorecard!$H$11:$H$51,3)<0.5,"", "Points lost: "&ROUND(LARGE(Scorecard!$H$11:$H$51,3),1)) -> Points lost: 4
A28: No | B28: MY CHECKLIST — WHAT I SAID AND WHAT I MISSED | C28: Points | D28: I got | E28: Mark | F28: What was missing
A29: A. VISIT & PHOTOS
A30: A1 | B30: =Scorecard!B11 -> Start with: Application ID, customer name, village/town, loan amount asked. Say that you checked the CRIF report and BPS score before going. | C30: =Scorecard!C11 -> 2 | D30: =Scorecard!F11 -> 0 | E30: =IF(Scorecard!E11="Yes","✔ Said",IF(Scorecard!E11="Half","½ Half",IF(Scorecard!E11="No","✘ MISSED","?"))) -> ? | F30: =IF(Scorecard!G11="","",Scorecard!G11)
A31: A2 ★ | B31: =Scorecard!B12 -> Say that you met the BORROWER HIMSELF at his business — not on phone, not through a relative. Date, time, and who came with you. | C31: =Scorecard!C12 -> 2 | D31: =Scorecard!F12 -> 0 | E31: =IF(Scorecard!E12="Yes","✔ Said",IF(Scorecard!E12="Half","½ Half",IF(Scorecard!E12="No","✘ MISSED","?"))) -> ? | F31: =IF(Scorecard!G12="","",Scorecard!G12)
A32: A3 | B32: =Scorecard!B13 -> Time spent: business (start–end) and home (start–end). Total must be at least 1 hour (normally 1 to 1.5 hours). | C32: =Scorecard!C13 -> 2 | D32: =Scorecard!F13 -> 0 | E32: =IF(Scorecard!E13="Yes","✔ Said",IF(Scorecard!E13="Half","½ Half",IF(Scorecard!E13="No","✘ MISSED","?"))) -> ? | F32: =IF(Scorecard!G13="","",Scorecard!G13)
A33: A4 | B33: =Scorecard!B14 -> Home and property visited (say if home and property are the same house). Co-borrower and family met at home. | C33: =Scorecard!C14 -> 2 | D33: =Scorecard!F14 -> 0 | E33: =IF(Scorecard!E14="Yes","✔ Said",IF(Scorecard!E14="Half","½ Half",IF(Scorecard!E14="No","✘ MISSED","?"))) -> ? | F33: =IF(Scorecard!G14="","",Scorecard!G14)
A34: A5 | B34: =Scorecard!B15 -> Photos taken and uploaded: signboard, QR code, FULL stock, purchase bills, sales bills / register / khata, mandi receipts, every room of the house, household items, electricity meter, both business neighbours, both home neighbours, land / animals (if any), property papers. | C34: =Scorecard!C15 -> 2 | D34: =Scorecard!F15 -> 0 | E34: =IF(Scorecard!E15="Yes","✔ Said",IF(Scorecard!E15="Half","½ Half",IF(Scorecard!E15="No","✘ MISSED","?"))) -> ? | F34: =IF(Scorecard!G15="","",Scorecard!G15)
A35: B. BUSINESS
A36: B1 ★ | B36: =Scorecard!B17 -> What you SAW: shop/unit size, how much stock, how many staff, customers during your visit, machines, signboard. Every business visited — including one run by wife, son, father. | C36: =Scorecard!C17 -> 3 | D36: =Scorecard!F17 -> 0 | E36: =IF(Scorecard!E17="Yes","✔ Said",IF(Scorecard!E17="Half","½ Half",IF(Scorecard!E17="No","✘ MISSED","?"))) -> ? | F36: =IF(Scorecard!G17="","",Scorecard!G17)
A37: B2 | B37: =Scorecard!B18 -> Who actually runs it; running since which year; what the borrower did BEFORE this; new business or family business for generations; shop owned or rented (rent, years here); licence seen (Udyam / Gumasta / GST / FSSAI). | C37: =Scorecard!C18 -> 3 | D37: =Scorecard!F18 -> 0 | E37: =IF(Scorecard!E18="Yes","✔ Said",IF(Scorecard!E18="Half","½ Half",IF(Scorecard!E18="No","✘ MISSED","?"))) -> ? | F37: =IF(Scorecard!G18="","",Scorecard!G18)
A38: B3 | B38: =Scorecard!B19 -> PURCHASES: buys material from where; purchase bills of last 12 months seen?; % paid by bank/UPI and % by cash; TOP 5 SUPPLIERS with names and mobile numbers; credit taken from suppliers (days, amount due). | C38: =Scorecard!C19 -> 4 | D38: =Scorecard!F19 -> 0 | E38: =IF(Scorecard!E19="Yes","✔ Said",IF(Scorecard!E19="Half","½ Half",IF(Scorecard!E19="No","✘ MISSED","?"))) -> ? | F38: =IF(Scorecard!G19="","",Scorecard!G19)
A39: B4 | B39: =Scorecard!B20 -> SALES: who buys; % received in cash and % by UPI; QR code / UPI is in WHOSE name; sales today and average daily sales; average monthly sales; lean months and daily sales in lean months; udhaar (credit) given to customers — how much. | C39: =Scorecard!C20 -> 4 | D39: =Scorecard!F20 -> 0 | E39: =IF(Scorecard!E20="Yes","✔ Said",IF(Scorecard!E20="Half","½ Half",IF(Scorecard!E20="No","✘ MISSED","?"))) -> ? | F39: =IF(Scorecard!G20="","",Scorecard!G20)
A40: B5 | B40: =Scorecard!B21 -> STOCK: you counted the stock yourself — your value (Rs.) vs what the customer says. | C40: =Scorecard!C21 -> 2 | D40: =Scorecard!F21 -> 0 | E40: =IF(Scorecard!E21="Yes","✔ Said",IF(Scorecard!E21="Half","½ Half",IF(Scorecard!E21="No","✘ MISSED","?"))) -> ? | F40: =IF(Scorecard!G21="","",Scorecard!G21)
A41: B6 | B41: =Scorecard!B22 -> INCOME — BALL-PARK only (no detailed maths needed at PD): (1) what the CUSTOMER says his monthly income from the business is, and (2) what YOU think the monthly income is, as a rough figure. Both numbers must be said. | C41: =Scorecard!C22 -> 4 | D41: =Scorecard!F22 -> 0 | E41: =IF(Scorecard!E22="Yes","✔ Said",IF(Scorecard!E22="Half","½ Half",IF(Scorecard!E22="No","✘ MISSED","?"))) -> ? | F41: =IF(Scorecard!G22="","",Scorecard!G22)
A42: B7 ★ | B42: =Scorecard!B23 -> AA (Account Aggregator) triggered on PRAGATI for ALL bank accounts of borrower and co-borrowers — name each account and say SUCCESS or FAILED for each. Documents seen: bills, register, khata, passbook, kata parchi. | C42: =Scorecard!C23 -> 3 | D42: =Scorecard!F23 -> 0 | E42: =IF(Scorecard!E23="Yes","✔ Said",IF(Scorecard!E23="Half","½ Half",IF(Scorecard!E23="No","✘ MISSED","?"))) -> ? | F42: =IF(Scorecard!G23="","",Scorecard!G23)
A43: B8 ★ | B43: =Scorecard!B24 -> 2 BUSINESS NEIGHBOURS: name, shop, mobile number, how long this business is running here, what they said about the customer. Photos taken. | C43: =Scorecard!C24 -> 4 | D43: =Scorecard!F24 -> 0 | E43: =IF(Scorecard!E24="Yes","✔ Said",IF(Scorecard!E24="Half","½ Half",IF(Scorecard!E24="No","✘ MISSED","?"))) -> ? | F43: =IF(Scorecard!G24="","",Scorecard!G24)
A44: B9 | B44: =Scorecard!B25 -> YOUR VIEW on each business: genuine and running — or doubt (borrowed stock, arranged setup, too small for the claim). Say it clearly. | C44: =Scorecard!C25 -> 3 | D44: =Scorecard!F25 -> 0 | E44: =IF(Scorecard!E25="Yes","✔ Said",IF(Scorecard!E25="Half","½ Half",IF(Scorecard!E25="No","✘ MISSED","?"))) -> ? | F44: =IF(Scorecard!G25="","",Scorecard!G25)
A45: C. FARM, DAIRY & OTHER FAMILY INCOME
...
