Workbook

Sheet Scorecard
A1: BM AUDIO FI — PHONE CALL RECORDING SCORECARD (V2.1 Simple)
A2: Evaluator: fill the yellow cells only. For each item choose Yes (asked / said fully with names and figures), Half (asked but vague or incomplete) or No (not asked). If the customer clearly says something does NOT exist (no land, no animals, no other income, no overdue) — that IS covered: mark YES. Score, result and the BM's "My Result" page fill automatically.
A4: Application ID | C4: Recording length (minutes)
A5: Customer name | C5: Recording uploaded on PRAGATI the same day? (Yes/No)
A6: BM name | C6: Both sides clearly audible? (Yes/No)
A7: Date of call & recording | C7: Evaluator
A9: No | B9: WHAT THE BM MUST ASK / SAY ON THE CALL | C9: Points | D9: MUST | E9: Covered? (Yes / Half / No) | F9: Score | G9: What was missing — evaluator note | H9: lost (helper)
A10: A. CALL OPENING & IDENTITY | C10: 10 | G10: Minute 0–1
A11: A1 | B11: Say at the start: "Yeh call record ho rahi hai, aapke loan verification ke liye." Then state Application ID, customer name and village/town. | C11: 3 | D11: MUST | F11: =IF(E11="Yes",C11,IF(E11="Half",C11/2,0)) -> 0 | H11: =IF(E11="Yes",0,IF(E11="Half",C11/2,C11)+(1000-ROW())/100000) -> 3.00989
A12: A2 | B12: Confirm you are talking to the MAIN BORROWER himself / herself — full name, this is his own number (on video: face matches the KYC photo). Not a relative, agent or anyone else. | C12: 3 | D12: MUST | F12: =IF(E12="Yes",C12,IF(E12="Half",C12/2,0)) -> 0 | H12: =IF(E12="Yes",0,IF(E12="Half",C12/2,C12)+(1000-ROW())/100000) -> 3.00988
A13: A3 | B13: Ask the customer: does he know that he has applied for a loan with PRODIGEE FINANCE LIMITED? Even if he does not say the name correctly, do NOT cut points — what matters is that the BM ASKS this on the call. | C13: 2 | F13: =IF(E13="Yes",C13,IF(E13="Half",C13/2,0)) -> 0 | H13: =IF(E13="Yes",0,IF(E13="Half",C13/2,C13)+(1000-ROW())/100000) -> 2.00987
A14: A4 | B14: Say that before calling you have seen the Prodigee BPS Score, the CRIF Score and the business photos of the borrower. | C14: 2 | F14: =IF(E14="Yes",C14,IF(E14="Half",C14/2,0)) -> 0 | H14: =IF(E14="Yes",0,IF(E14="Half",C14/2,C14)+(1000-ROW())/100000) -> 2.00986
A15: B. SOURCING, RM VISIT & LOGIN FEE | C15: 12 | G15: Minute 1–3
A16: B1 | B16: Who came to log in the file — the RM's NAME, and WHEN did he visit? Did he visit the business AND the home? | C16: 4 | F16: =IF(E16="Yes",C16,IF(E16="Half",C16/2,0)) -> 0 | H16: =IF(E16="Yes",0,IF(E16="Half",C16/2,C16)+(1000-ROW())/100000) -> 4.00984
A17: B2 | B17: LOGIN FEE: how much was collected, by WHOM (must be the Prodigee RM himself), and was a receipt given. Amount must match PRAGATI. | C17: 4 | D17: MUST | F17: =IF(E17="Yes",C17,IF(E17="Half",C17/2,0)) -> 0 | H17: =IF(E17="Yes",0,IF(E17="Half",C17/2,C17)+(1000-ROW())/100000) -> 4.00983
A18: B3 | B18: Ask directly: any agent, broker, DSA or connector in between? Did ANYONE ask for commission, fees or money for this loan? Tell the customer: Prodigee has ZERO COMMISSION — pay nobody. | C18: 4 | D18: MUST | F18: =IF(E18="Yes",C18,IF(E18="Half",C18/2,0)) -> 0 | H18: =IF(E18="Yes",0,IF(E18="Half",C18/2,C18)+(1000-ROW())/100000) -> 4.00982
A19: C. LOAN, PRODUCT & END USE | C19: 12 | G19: Minute 3–5
A20: C1 | B20: Customer clearly understands: this is a BUSINESS Loan Against Property — the property will be MORTGAGED to Prodigee. | C20: 2 | D20: MUST | F20: =IF(E20="Yes",C20,IF(E20="Half",C20/2,0)) -> 0 | H20: =IF(E20="Yes",0,IF(E20="Half",C20/2,C20)+(1000-ROW())/100000) -> 2.0098
A21: C2 | B21: LOAN AMOUNT: check the loan amount the customer requires. | C21: 2 | D21: MUST | F21: =IF(E21="Yes",C21,IF(E21="Half",C21/2,0)) -> 0 | H21: =IF(E21="Yes",0,IF(E21="Half",C21/2,C21)+(1000-ROW())/100000) -> 2.00979
A22: C3 | B22: END USE: what the money is for — how much, for what, when. Business-linked and not a restricted use. | C22: 2 | F22: =IF(E22="Yes",C22,IF(E22="Half",C22/2,0)) -> 0 | H22: =IF(E22="Yes",0,IF(E22="Half",C22/2,C22)+(1000-ROW())/100000) -> 2.00978
A23: C4 | B23: FRESH or BT? Is this a FRESH loan requirement, or a Balance Transfer (BT) from an existing lender? Is there already a loan on this property that the customer wants us to take over and give additional (top-up) funds? | C23: 6 | F23: =IF(E23="Yes",C23,IF(E23="Half",C23/2,0)) -> 0 | H23: =IF(E23="Yes",0,IF(E23="Half",C23/2,C23)+(1000-ROW())/100000) -> 6.00977
A24: D. ALL INCOMES OF THE HOUSEHOLD | C24: 28 | G24: Minute 5–9
A25: D1 | B25: PRIMARY BUSINESS: what, where, since when, who runs it. Average DAILY sales / income and MONTHLY income — in the customer's own figures. | C25: 6 | F25: =IF(E25="Yes",C25,IF(E25="Half",C25/2,0)) -> 0 | H25: =IF(E25="Yes",0,IF(E25="Half",C25/2,C25)+(1000-ROW())/100000) -> 6.00975
A26: D2 | B26: OTHER BUSINESSES run by the borrower or co-borrowers — each one with its average daily and monthly income. | C26: 6 | F26: =IF(E26="Yes",C26,IF(E26="Half",C26/2,0)) -> 0 | H26: =IF(E26="Yes",0,IF(E26="Half",C26/2,C26)+(1000-ROW())/100000) -> 6.00974
A27: D3 | B27: ADDITIONAL INCOMES: salary, rent, pension, transport, family members' earnings — source and monthly amount for each. | C27: 5 | F27: =IF(E27="Yes",C27,IF(E27="Half",C27/2,0)) -> 0 | H27: =IF(E27="Yes",0,IF(E27="Half",C27/2,C27)+(1000-ROW())/100000) -> 5.00973
A28: D4 | B28: AGRICULTURE & DAIRY: land — acres, in whose name; crops; approximate yearly income; KCC running? Any dairy / animals — if yes, how many animals and how many litres of milk per day. If no farm land or no animals, the customer says so clearly (counts as covered). | C28: 5 | F28: =IF(E28="Yes",C28,IF(E28="Half",C28/2,0)) -> 0 | H28: =IF(E28="Yes",0,IF(E28="Half",C28/2,C28)+(1000-ROW())/100000) -> 5.00972
A29: D5 | B29: Ask the customer: is the income of the WHOLE HOUSEHOLD put together more than Rs. 30,000 per month (NOT counting agriculture income)? Yes / No. | C29: 6 | D29: MUST | F29: =IF(E29="Yes",C29,IF(E29="Half",C29/2,0)) -> 0 | H29: =IF(E29="Yes",0,IF(E29="Half",C29/2,C29)+(1000-ROW())/100000) -> 6.00971
A30: E. CURRENT LOANS & OTHER APPLICATIONS | C30: 16 | G30: Minute 9–11
A31: E1 | B31: ACTIVE LOANS: every active loan — lender, EMI, since when — checked with the customer against the BPS / CRIF. Closed loans need NOT be checked. | C31: 6 | D31: MUST | F31: =IF(E31="Yes",C31,IF(E31="Half",C31/2,0)) -> 0 | H31: =IF(E31="Yes",0,IF(E31="Half",C31/2,C31)+(1000-ROW())/100000) -> 6.00969
A32: E2 | B32: OVERDUES: for every active loan overdue NOW — and any overdue in the PAST — ask the customer the reason. If there is no overdue, say so. | C32: 5 | F32: =IF(E32="Yes",C32,IF(E32="Half",C32/2,0)) -> 0 | H32: =IF(E32="Yes",0,IF(E32="Half",C32/2,C32)+(1000-ROW())/100000) -> 5.00968
A33: E3 | B33: APPLIED ANYWHERE ELSE? Which bank / NBFC, how much, when, and the STATUS — sanctioned / rejected / pending — and why. | C33: 5 | D33: MUST | F33: =IF(E33="Yes",C33,IF(E33="Half",C33/2,0)) -> 0 | H33: =IF(E33="Yes",0,IF(E33="Half",C33/2,C33)+(1000-ROW())/100000) -> 5.00967
A34: F. COLLATERAL PROPERTY | C34: 16 | G34: Minute 11–13
A35: F1 | B35: WHICH PROPERTY will be mortgaged: house / shop / plot, where, self-occupied or rented out, approximate size. | C35: 4 | F35: =IF(E35="Yes",C35,IF(E35="Half",C35/2,0)) -> 0 | H35: =IF(E35="Yes",0,IF(E35="Half",C35/2,C35)+(1000-ROW())/100000) -> 4.00965
A36: F2 | B36: PROPERTY PAPERS: what type the customer will give — Registered Sale Deed / Patta / 5-pager / other; are the ORIGINALS with him? | C36: 4 | D36: MUST | F36: =IF(E36="Yes",C36,IF(E36="Half",C36/2,0)) -> 0 | H36: =IF(E36="Yes",0,IF(E36="Half",C36/2,C36)+(1000-ROW())/100000) -> 4.00964
A37: F3 | B37: ALREADY MORTGAGED anywhere? Papers lying with any bank / finance company? Is he willing to mortgage it? | C37: 4 | D37: MUST | F37: =IF(E37="Yes",C37,IF(E37="Half",C37/2,0)) -> 0 | H37: =IF(E37="Yes",0,IF(E37="Half",C37/2,C37)+(1000-ROW())/100000) -> 4.00963
A38: F4 | B38: OWNERS: who all are the owners of the property — will ALL of them come as CO-BORROWERS? FEMALE CO-BORROWER IS MANDATORY — wife (or mother, if unmarried): her name, and has she agreed? | C38: 4 | D38: MUST | F38: =IF(E38="Yes",C38,IF(E38="Half",C38/2,0)) -> 0 | H38: =IF(E38="Yes",0,IF(E38="Half",C38/2,C38)+(1000-ROW())/100000) -> 4.00962
A39: G. CALL CONDUCT & NEXT STEPS | C39: 6 | G39: Minute 13–15
A40: G1 | B40: Call 5 to 15 minutes, both sides audible end to end. Open questions — the customer speaks first; no feeding of figures; nobody prompting him in the background. | C40: 3 | F40: =IF(E40="Yes",C40,IF(E40="Half",C40/2,0)) -> 0 | H40: =IF(E40="Yes",0,IF(E40="Half",C40/2,C40)+(1000-ROW())/100000) -> 3.0096
A41: G2 | B41: Tell the customer the next steps: the file goes to the Credit Team; a Credit call will come; then the BCM will visit the business and the home. Clean Track Reward (last 3 EMIs waived on clean repayment). Pay nobody any commission. | C41: 3 | F41: =IF(E41="Yes",C41,IF(E41="Half",C41/2,0)) -> 0 | H41: =IF(E41="Yes",0,IF(E41="Half",C41/2,C41)+(1000-ROW())/100000) -> 3.00959
A43: Recording valid? (5–15 minutes, uploaded same day, audible) | C43: =IF(OR(E4="",E5="",E6=""),"Fill length, same-day and audible",IF(AND(E4>=5,E4<=15,E5="Yes",E6="Yes"),"YES","NO — not accepted")) -> Fill length, same-day and audible
...

Sheet My Result
A1: MY FI CALL RESULT
A2: Read this after every FI call. It shows your score, what you missed and what to ask first next time. Nothing to fill here — it comes from the Scorecard.
A4: BM | C4: =Scorecard!B6 -> 0
A5: Customer | C5: =Scorecard!B5 -> 0
A6: Application ID | C6: =Scorecard!B4 -> 0
A7: Date | C7: =Scorecard!B7 -> 0
A8: Recording length (min) | C8: =Scorecard!E4 -> 0
A10: MY SCORE | C10: =Scorecard!C46&" / 100" -> 0 / 100
A11: RESULT | C11: =Scorecard!C49 -> NOT ACCEPTED — recording under 5 min / over 15 min / not uploaded same day / not audible. Call again.
A12: Minimum to pass: 75. All MUST items must be Yes. 90+ is Excellent.
B14: HOW I DID — GROUP-WISE | C14: Points | D14: I got | E14: % | F14: Comment
A15: A | B15: Call Opening & Identity | C15: 10 | D15: =SUM(Scorecard!F11:F14) -> 0 | E15: =ROUND(D15/C15*100,0)&"%" -> 0% | F15: =IF(D15=C15,"Fully covered",IF(D15>=C15*0.75,"Good — small gaps",IF(D15>=C15*0.5,"Weak — see items below","Mostly missed — see items below"))) -> Mostly missed — see items below
A16: B | B16: Sourcing, RM Visit & Login Fee | C16: 12 | D16: =SUM(Scorecard!F16:F18) -> 0 | E16: =ROUND(D16/C16*100,0)&"%" -> 0% | F16: =IF(D16=C16,"Fully covered",IF(D16>=C16*0.75,"Good — small gaps",IF(D16>=C16*0.5,"Weak — see items below","Mostly missed — see items below"))) -> Mostly missed — see items below
A17: C | B17: Loan, Product & End Use | C17: 12 | D17: =SUM(Scorecard!F20:F23) -> 0 | E17: =ROUND(D17/C17*100,0)&"%" -> 0% | F17: =IF(D17=C17,"Fully covered",IF(D17>=C17*0.75,"Good — small gaps",IF(D17>=C17*0.5,"Weak — see items below","Mostly missed — see items below"))) -> Mostly missed — see items below
A18: D | B18: All Incomes Of The Household | C18: 28 | D18: =SUM(Scorecard!F25:F29) -> 0 | E18: =ROUND(D18/C18*100,0)&"%" -> 0% | F18: =IF(D18=C18,"Fully covered",IF(D18>=C18*0.75,"Good — small gaps",IF(D18>=C18*0.5,"Weak — see items below","Mostly missed — see items below"))) -> Mostly missed — see items below
A19: E | B19: Current Loans & Other Applications | C19: 16 | D19: =SUM(Scorecard!F31:F33) -> 0 | E19: =ROUND(D19/C19*100,0)&"%" -> 0% | F19: =IF(D19=C19,"Fully covered",IF(D19>=C19*0.75,"Good — small gaps",IF(D19>=C19*0.5,"Weak — see items below","Mostly missed — see items below"))) -> Mostly missed — see items below
A20: F | B20: Collateral Property | C20: 16 | D20: =SUM(Scorecard!F35:F38) -> 0 | E20: =ROUND(D20/C20*100,0)&"%" -> 0% | F20: =IF(D20=C20,"Fully covered",IF(D20>=C20*0.75,"Good — small gaps",IF(D20>=C20*0.5,"Weak — see items below","Mostly missed — see items below"))) -> Mostly missed — see items below
A21: G | B21: Call Conduct & Next Steps | C21: 6 | D21: =SUM(Scorecard!F40:F41) -> 0 | E21: =ROUND(D21/C21*100,0)&"%" -> 0% | F21: =IF(D21=C21,"Fully covered",IF(D21>=C21*0.75,"Good — small gaps",IF(D21>=C21*0.5,"Weak — see items below","Mostly missed — see items below"))) -> Mostly missed — see items below
A23: NEXT TIME — ASK THESE FIRST (the 3 items where I lost most points)
A24: 1 | B24: =IF(LARGE(Scorecard!$H$11:$H$41,1)<0.5,"—",INDEX(Scorecard!$A$11:$A$41,MATCH(LARGE(Scorecard!$H$11:$H$41,1),Scorecard!$H$11:$H$41,0))&" — "&INDEX(Scorecard!$B$11:$B$41,MATCH(LARGE(Scorecard!$H$11:$H$41,1),Scorecard!$H$11:$H$41,0))) -> C4 — FRESH or BT? Is this a FRESH loan requirement, or a Balance Transfer (BT) from an existing lender? Is there already a loan on this property that the customer wants us to take over and give additional (top-up) funds? | F24: =IF(LARGE(Scorecard!$H$11:$H$41,1)<0.5,"","Points lost: "&ROUND(LARGE(Scorecard!$H$11:$H$41,1),1)) -> Points lost: 6
A25: 2 | B25: =IF(LARGE(Scorecard!$H$11:$H$41,2)<0.5,"—",INDEX(Scorecard!$A$11:$A$41,MATCH(LARGE(Scorecard!$H$11:$H$41,2),Scorecard!$H$11:$H$41,0))&" — "&INDEX(Scorecard!$B$11:$B$41,MATCH(LARGE(Scorecard!$H$11:$H$41,2),Scorecard!$H$11:$H$41,0))) -> D1 — PRIMARY BUSINESS: what, where, since when, who runs it. Average DAILY sales / income and MONTHLY income — in the customer's own figures. | F25: =IF(LARGE(Scorecard!$H$11:$H$41,2)<0.5,"","Points lost: "&ROUND(LARGE(Scorecard!$H$11:$H$41,2),1)) -> Points lost: 6
A26: 3 | B26: =IF(LARGE(Scorecard!$H$11:$H$41,3)<0.5,"—",INDEX(Scorecard!$A$11:$A$41,MATCH(LARGE(Scorecard!$H$11:$H$41,3),Scorecard!$H$11:$H$41,0))&" — "&INDEX(Scorecard!$B$11:$B$41,MATCH(LARGE(Scorecard!$H$11:$H$41,3),Scorecard!$H$11:$H$41,0))) -> D2 — OTHER BUSINESSES run by the borrower or co-borrowers — each one with its average daily and monthly income. | F26: =IF(LARGE(Scorecard!$H$11:$H$41,3)<0.5,"","Points lost: "&ROUND(LARGE(Scorecard!$H$11:$H$41,3),1)) -> Points lost: 6
A28: No | B28: MY CHECKLIST — WHAT I ASKED AND WHAT I MISSED | C28: Points | D28: I got | E28: Mark | F28: What was missing
A29: A. CALL OPENING & IDENTITY
A30: A1 ★ | B30: =Scorecard!B11 -> Say at the start: "Yeh call record ho rahi hai, aapke loan verification ke liye." Then state Application ID, customer name and village/town. | C30: =Scorecard!C11 -> 3 | D30: =Scorecard!F11 -> 0 | E30: =IF(Scorecard!E11="Yes","✔ Asked",IF(Scorecard!E11="Half","½ Half",IF(Scorecard!E11="No","✘ MISSED","?"))) -> ? | F30: =IF(Scorecard!G11="","",Scorecard!G11)
A31: A2 ★ | B31: =Scorecard!B12 -> Confirm you are talking to the MAIN BORROWER himself / herself — full name, this is his own number (on video: face matches the KYC photo). Not a relative, agent or anyone else. | C31: =Scorecard!C12 -> 3 | D31: =Scorecard!F12 -> 0 | E31: =IF(Scorecard!E12="Yes","✔ Asked",IF(Scorecard!E12="Half","½ Half",IF(Scorecard!E12="No","✘ MISSED","?"))) -> ? | F31: =IF(Scorecard!G12="","",Scorecard!G12)
A32: A3 | B32: =Scorecard!B13 -> Ask the customer: does he know that he has applied for a loan with PRODIGEE FINANCE LIMITED? Even if he does not say the name correctly, do NOT cut points — what matters is that the BM ASKS this on the call. | C32: =Scorecard!C13 -> 2 | D32: =Scorecard!F13 -> 0 | E32: =IF(Scorecard!E13="Yes","✔ Asked",IF(Scorecard!E13="Half","½ Half",IF(Scorecard!E13="No","✘ MISSED","?"))) -> ? | F32: =IF(Scorecard!G13="","",Scorecard!G13)
A33: A4 | B33: =Scorecard!B14 -> Say that before calling you have seen the Prodigee BPS Score, the CRIF Score and the business photos of the borrower. | C33: =Scorecard!C14 -> 2 | D33: =Scorecard!F14 -> 0 | E33: =IF(Scorecard!E14="Yes","✔ Asked",IF(Scorecard!E14="Half","½ Half",IF(Scorecard!E14="No","✘ MISSED","?"))) -> ? | F33: =IF(Scorecard!G14="","",Scorecard!G14)
A34: B. SOURCING, RM VISIT & LOGIN FEE
A35: B1 | B35: =Scorecard!B16 -> Who came to log in the file — the RM's NAME, and WHEN did he visit? Did he visit the business AND the home? | C35: =Scorecard!C16 -> 4 | D35: =Scorecard!F16 -> 0 | E35: =IF(Scorecard!E16="Yes","✔ Asked",IF(Scorecard!E16="Half","½ Half",IF(Scorecard!E16="No","✘ MISSED","?"))) -> ? | F35: =IF(Scorecard!G16="","",Scorecard!G16)
A36: B2 ★ | B36: =Scorecard!B17 -> LOGIN FEE: how much was collected, by WHOM (must be the Prodigee RM himself), and was a receipt given. Amount must match PRAGATI. | C36: =Scorecard!C17 -> 4 | D36: =Scorecard!F17 -> 0 | E36: =IF(Scorecard!E17="Yes","✔ Asked",IF(Scorecard!E17="Half","½ Half",IF(Scorecard!E17="No","✘ MISSED","?"))) -> ? | F36: =IF(Scorecard!G17="","",Scorecard!G17)
A37: B3 ★ | B37: =Scorecard!B18 -> Ask directly: any agent, broker, DSA or connector in between? Did ANYONE ask for commission, fees or money for this loan? Tell the customer: Prodigee has ZERO COMMISSION — pay nobody. | C37: =Scorecard!C18 -> 4 | D37: =Scorecard!F18 -> 0 | E37: =IF(Scorecard!E18="Yes","✔ Asked",IF(Scorecard!E18="Half","½ Half",IF(Scorecard!E18="No","✘ MISSED","?"))) -> ? | F37: =IF(Scorecard!G18="","",Scorecard!G18)
A38: C. LOAN, PRODUCT & END USE
A39: C1 ★ | B39: =Scorecard!B20 -> Customer clearly understands: this is a BUSINESS Loan Against Property — the property will be MORTGAGED to Prodigee. | C39: =Scorecard!C20 -> 2 | D39: =Scorecard!F20 -> 0 | E39: =IF(Scorecard!E20="Yes","✔ Asked",IF(Scorecard!E20="Half","½ Half",IF(Scorecard!E20="No","✘ MISSED","?"))) -> ? | F39: =IF(Scorecard!G20="","",Scorecard!G20)
A40: C2 ★ | B40: =Scorecard!B21 -> LOAN AMOUNT: check the loan amount the customer requires. | C40: =Scorecard!C21 -> 2 | D40: =Scorecard!F21 -> 0 | E40: =IF(Scorecard!E21="Yes","✔ Asked",IF(Scorecard!E21="Half","½ Half",IF(Scorecard!E21="No","✘ MISSED","?"))) -> ? | F40: =IF(Scorecard!G21="","",Scorecard!G21)
A41: C3 | B41: =Scorecard!B22 -> END USE: what the money is for — how much, for what, when. Business-linked and not a restricted use. | C41: =Scorecard!C22 -> 2 | D41: =Scorecard!F22 -> 0 | E41: =IF(Scorecard!E22="Yes","✔ Asked",IF(Scorecard!E22="Half","½ Half",IF(Scorecard!E22="No","✘ MISSED","?"))) -> ? | F41: =IF(Scorecard!G22="","",Scorecard!G22)
A42: C4 | B42: =Scorecard!B23 -> FRESH or BT? Is this a FRESH loan requirement, or a Balance Transfer (BT) from an existing lender? Is there already a loan on this property that the customer wants us to take over and give additional (top-up) funds? | C42: =Scorecard!C23 -> 6 | D42: =Scorecard!F23 -> 0 | E42: =IF(Scorecard!E23="Yes","✔ Asked",IF(Scorecard!E23="Half","½ Half",IF(Scorecard!E23="No","✘ MISSED","?"))) -> ? | F42: =IF(Scorecard!G23="","",Scorecard!G23)
A43: D. ALL INCOMES OF THE HOUSEHOLD
A44: D1 | B44: =Scorecard!B25 -> PRIMARY BUSINESS: what, where, since when, who runs it. Average DAILY sales / income and MONTHLY income — in the customer's own figures. | C44: =Scorecard!C25 -> 6 | D44: =Scorecard!F25 -> 0 | E44: =IF(Scorecard!E25="Yes","✔ Asked",IF(Scorecard!E25="Half","½ Half",IF(Scorecard!E25="No","✘ MISSED","?"))) -> ? | F44: =IF(Scorecard!G25="","",Scorecard!G25)
A45: D2 | B45: =Scorecard!B26 -> OTHER BUSINESSES run by the borrower or co-borrowers — each one with its average daily and monthly income. | C45: =Scorecard!C26 -> 6 | D45: =Scorecard!F26 -> 0 | E45: =IF(Scorecard!E26="Yes","✔ Asked",IF(Scorecard!E26="Half","½ Half",IF(Scorecard!E26="No","✘ MISSED","?"))) -> ? | F45: =IF(Scorecard!G26="","",Scorecard!G26)
...
